<?xml version="1.0" ?>
<robot name="fr3_gripper">
  <material name="Silver">
    <color rgba="1.0 1.0 1.0 1.0" />
  </material>
  <material name="Black">
    <color rgba="0.0 0.0 0.0 1.0" />
  </material>
  <material name="Chrome">
    <color rgba="0.0 0.0 0.0 1.0" />
  </material>
  <material name="DarkGrey">panda_
    <color rgba="0.33 0.33 0.33 1.0" />
  </material>
  <material name="Grey">
    <color rgba="0.55 0.55 0.55 0.8" />
  </material>
  <material name="OpaqueGreen">
    <color rgba="0.0 1.0 0.0 0.2" />
  </material>
  <material name="OpaqueRed">
    <color rgba="1.0 0.0 0.0 0.2" />
  </material>

  <link name="panda_link0">
    <inertial>
      <mass value="2.92"/>
      <origin rpy="0 0 0" xyz="-0.025566 -2.88e-05 0.057332"/>
      <inertia ixx="0.00782229414331" ixy="-1.56191622996e-05" ixz="-0.00126005738123" iyy="0.0109027971813" iyz="1.08233858202e-05" izz="0.0102355503949"/>
    </inertial>
    <visual>
      <geometry>
        <mesh filename="package://robot_payload_id/assets/fr3/visual/link0.dae" />
      </geometry>
    </visual>
    <collision>
      <geometry>
        <mesh filename="package://robot_payload_id/assets/fr3/collision/link0.obj" scale="1.0 1.0 1.0"/>
      </geometry>
    </collision>
  </link>

  <joint name="panda_joint1" type="revolute">
    <safety_controller k_position="100.0" k_velocity="40.0" soft_lower_limit="-2.8973" soft_upper_limit="2.8973" />
    <origin rpy="-7.070853699609467e-20 7.01457620144154e-17 -5.871445110820177e-17" xyz="1.6453621370977905e-17 8.128699592849844e-17 0.3330000000000001" />
    <parent link="panda_link0" />
    <child link="panda_link1" />
    <axis xyz="0 0 1" />
    <limit effort="87" lower="-2.3093" upper="2.3093" velocity="2.0"/>
    <!-- <limit effort="87" lower="-2.3093" upper="2.3093" velocity="2.62"/> -->
  </joint>

  <link name="panda_link1">
    <inertial>
      <mass value="2.74"/>
      <origin rpy="0 0 0" xyz="0 -0.0324958 -0.0675818"/>
      <inertia ixx="0.0180416958283" ixy="0.0" ixz="0.0" iyy="0.0159136071891" iyz="0.0046758424612" izz="0.00620690827127"/>
    </inertial>
    <visual>
      <geometry>
        <mesh filename="package://robot_payload_id/assets/fr3/visual/link1.dae" />
      </geometry>
    </visual>
    <collision>
      <geometry>
        <mesh filename="package://robot_payload_id/assets/fr3/collision/link1.obj" scale="1.0 1.0 1.0"/>
      </geometry>
    </collision>
  </link>

  <joint name="panda_joint2" type="revolute">
    <safety_controller k_position="100.0" k_velocity="40.0" soft_lower_limit="-1.7628" soft_upper_limit="1.7628" />
    <origin rpy="-1.569663240507509 2.1599930128152177e-05 -1.8298134019183714e-12" xyz="-0.00022476212368955053 0.000203106104820772 2.8230196526247564e-17" />
    <parent link="panda_link1" />
    <child link="panda_link2" />
    <axis xyz="0 0 1" />
    <limit effort="87.0" lower="-1.5133" upper="1.5133" velocity="1.0" />
    <!-- <limit effort="87.0" lower="-1.5133" upper="1.5133" velocity="2.62" /> -->
  </joint>

  <link name="panda_link2">
    <inertial>
      <mass value="2.74"/>
      <origin rpy="0 0 0" xyz="0 -0.06861 0.0322285"/>
      <inertia ixx="0.0182856182281" ixy="0.0" ixz="0.0" iyy="0.00621358421175" iyz="-0.00472844221905" izz="0.0161514346309"/>
    </inertial>
    <visual>
      <geometry>
        <mesh filename="package://robot_payload_id/assets/fr3/visual/link2.dae" />
      </geometry>
    </visual>
    <collision>
      <geometry>
        <mesh filename="package://robot_payload_id/assets/fr3/collision/link2.obj" scale="1.0 1.0 1.0"/>
      </geometry>
    </collision>
  </link>

  <joint name="panda_joint3" type="revolute">
    <safety_controller k_position="100.0" k_velocity="40.0" soft_lower_limit="-2.8973" soft_upper_limit="2.8973" />
    <origin rpy="1.5699746877243725 -0.0010472273004368765 1.3751793428407215e-05" xyz="2.483591980168594e-05 -0.31585675510886724 0.00020310596611635017" />
    <parent link="panda_link2" />
    <child link="panda_link3" />
    <axis xyz="0 0 1" />
    <limit effort="87.0" lower="-2.4937" upper="2.4937" velocity="1.5" />
    <!-- <limit effort="87.0" lower="-2.4937" upper="2.4937" velocity="2.62" /> -->
  </joint>

  <link name="panda_link3">
    <inertial>
      <mass value="2.38"/>
      <origin rpy="0 0 0" xyz="0.0469893 0.0316374 -0.031704"/>
      <inertia ixx="0.00771376630908" ixy="-0.00248490625138" ixz="-0.00332147581033" iyy="0.00989108008727" iyz="-0.00217796151484" izz="0.00811723558464"/>
    </inertial>
    <visual>
      <geometry>
        <mesh filename="package://robot_payload_id/assets/fr3/visual/link3.dae" />
      </geometry>
    </visual>
    <collision>
      <geometry>
        <mesh filename="package://robot_payload_id/assets/fr3/collision/link3.obj" scale="1.0 1.0 1.0"/>
      </geometry>
    </collision>
  </link>

  <joint name="panda_joint4" type="revolute">
    <safety_controller k_position="100.0" k_velocity="40.0" soft_lower_limit="-3.0718" soft_upper_limit="0.0175" />
    <origin rpy="1.5689175804611115 0.0007229190055229249 0.0010286904104520262" xyz="0.08238210033982035 0.000224830817889553 -0.00014307764469451107" />
    <parent link="panda_link3" />
    <child link="panda_link4" />
    <axis xyz="0 0 1" />
    <limit effort="87.0" lower="-2.7478" upper="-0.4461" velocity="1.25" />
    <!-- <limit effort="87.0" lower="-2.7478" upper="-0.4461" velocity="2.62" /> -->
  </joint>

  <link name="panda_link4">
    <inertial>
      <mass value="2.38"/>
      <origin rpy="0 0 0" xyz="-0.0360446 0.0336853 0.031882"/>
      <inertia ixx="0.00799663881132" ixy="0.00347095570217" ixz="-0.00241222942995" iyy="0.00825390705278" iyz="0.00235774044121" izz="0.0102515004345"/>
    </inertial>
    <visual>
      <geometry>
        <mesh filename="package://robot_payload_id/assets/fr3/visual/link4.dae" />
      </geometry>
    </visual>
    <collision>
      <geometry>
        <mesh filename="package://robot_payload_id/assets/fr3/collision/link4.obj" scale="1.0 1.0 1.0"/>
      </geometry>
    </collision>
  </link>

  <joint name="panda_joint5" type="revolute">
      <safety_controller k_position="100.0" k_velocity="40.0" soft_lower_limit="-2.8973" soft_upper_limit="2.8973" />
      <origin rpy="-1.5725568343411012 0.002818808125247204 -0.0008331711560464819" xyz="-0.08277427447127986 0.38391682272804906 -0.0002252205503509532" />
      <parent link="panda_link4" />
      <child link="panda_link5" />
      <axis xyz="0 0 1" />
      <limit effort="12.0" lower="-2.48" upper="2.48" velocity="3.0" />
      <!-- <limit effort="12.0" lower="-2.48" upper="2.48" velocity="5.26" /> -->
  </joint>

  <link name="panda_link5">
    <inertial>
      <mass value="2.74"/>
      <origin rpy="0 0 0" xyz="0 0.0610427 -0.104176"/>
      <inertia ixx="0.030371374513" ixy="6.50283587108e-07" ixz="-1.05129179916e-05" iyy="0.0288752887402" iyz="-0.00775653445787" izz="0.00444134056164"/>
    </inertial>
    <visual>
      <geometry>
        <mesh filename="package://robot_payload_id/assets/fr3/visual/link5.dae" />
      </geometry>
    </visual>
    <collision>
      <geometry>
        <mesh filename="package://robot_payload_id/assets/fr3/collision/link5.obj" scale="1.0 1.0 1.0"/>
      </geometry>
    </collision>
  </link>

  <joint name="panda_joint6" type="revolute">
    <safety_controller k_position="100.0" k_velocity="40.0" soft_lower_limit="-0.0175" soft_upper_limit="3.7525" />
    <origin rpy="1.5664543458823141 0.0005001399131159785 0.002820279303635351" xyz="0.0007331599331725679 0.0002672518669462526 -8.300776996215768e-05" />
    <parent link="panda_link5" />
    <child link="panda_link6" />
    <axis xyz="0 0 1" />
    <limit effort="12.0" lower="0.8521" upper="4.2094" velocity="1.5" />
    <!-- <limit effort="12.0" lower="0.8521" upper="4.2094" velocity="4.18" /> -->
  </joint>

  <link name="panda_link6">
    <inertial>
      <mass value="1.55"/>
      <origin rpy="0 0 0" xyz="0.0510509 0.009108 0.0106343"/>
      <inertia ixx="0.00303336450376" ixy="-0.000437276865508" ixz="0.000629257294877" iyy="0.00404479911567" iyz="0.000130472021025" izz="0.00558234286039"/>
    </inertial>
    <visual>
      <geometry>
        <mesh filename="package://robot_payload_id/assets/fr3/visual/link6.dae" />
      </geometry>
    </visual>
    <collision>
      <geometry>
        <mesh filename="package://robot_payload_id/assets/fr3/collision/link6.obj" scale="1.0 1.0 1.0"/>
      </geometry>
    </collision>
  </link>

  <joint name="panda_joint7" type="revolute">
    <safety_controller k_position="100.0" k_velocity="40.0" soft_lower_limit="-2.8973" soft_upper_limit="2.8973" />
    <origin rpy="1.5708749860536488 2.9911583861364804e-08 -0.0003802655003243309" xyz="0.08680641996738661 -0.0012231086910573829 -0.00026553941424996123" />
    <parent link="panda_link6" />
    <child link="panda_link7" />
    <axis xyz="0 0 1" />
    <limit effort="12.0" lower="-2.6895" upper="2.6895" velocity="3.0" />
    <!-- <limit effort="12.0" lower="-2.6895" upper="2.6895" velocity="5.26" /> -->
  </joint>

  <link name="panda_link7">
    <inertial>
      <mass value="0.54"/>
      <origin rpy="0 0 0" xyz="0.0109695 0.0107965 0.0650411"/>
      <inertia ixx="0.000888868887021" ixy="-0.00012239074652" ixz="3.98699829666e-05" iyy="0.000888001373233" iyz="-9.33825115206e-05" izz="0.0007176834609"/>
    </inertial>
    <visual>
      <geometry>
        <mesh filename="package://robot_payload_id/assets/fr3/visual/link7.dae" />
      </geometry>
    </visual>
    <collision>
      <geometry>
        <mesh filename="package://robot_payload_id/assets/fr3/collision/link7.obj" scale="1.0 1.0 1.0"/>
      </geometry>
    </collision>
  </link>
  <transmission name="panda_tran1">
    <type>transmission_interface/SimpleTransmission</type>
    <joint name="panda_joint1">
      <hardwareInterface>PositionJointInterface</hardwareInterface>
    </joint>
    <actuator name="panda_motor1">
      <hardwareInterface>PositionJointInterface</hardwareInterface>
      <mechanicalReduction>1</mechanicalReduction>
      <drake:gear_ratio value="100.0" />
      <drake:rotor_inertia value="0.0000605721456" />
    </actuator>
  </transmission>
  <transmission name="panda_tran2">
    <type>transmission_interface/SimpleTransmission</type>
    <joint name="panda_joint2">
      <hardwareInterface>PositionJointInterface</hardwareInterface>
    </joint>
    <actuator name="panda_motor2">
      <hardwareInterface>PositionJointInterface</hardwareInterface>
      <mechanicalReduction>1</mechanicalReduction>
      <drake:gear_ratio value="100.0" />
      <drake:rotor_inertia value="0.0000605721456" />
    </actuator>
  </transmission>
  <transmission name="panda_tran3">
    <type>transmission_interface/SimpleTransmission</type>
    <joint name="panda_joint3">
      <hardwareInterface>PositionJointInterface</hardwareInterface>
    </joint>
    <actuator name="panda_motor3">
      <hardwareInterface>PositionJointInterface</hardwareInterface>
      <mechanicalReduction>1</mechanicalReduction>
      <drake:gear_ratio value="100.0" />
      <drake:rotor_inertia value="0.0000462474144" />
    </actuator>
  </transmission>
  <transmission name="panda_tran4">
    <type>transmission_interface/SimpleTransmission</type>
    <joint name="panda_joint4">
      <hardwareInterface>PositionJointInterface</hardwareInterface>
    </joint>
    <actuator name="panda_motor4">
      <hardwareInterface>PositionJointInterface</hardwareInterface>
      <mechanicalReduction>1</mechanicalReduction>
      <drake:gear_ratio value="100.0" />
      <drake:rotor_inertia value="0.0000462474144" />
    </actuator>
  </transmission>
  <transmission name="panda_tran5">
    <type>transmission_interface/SimpleTransmission</type>
    <joint name="panda_joint5">
      <hardwareInterface>PositionJointInterface</hardwareInterface>
    </joint>
    <actuator name="panda_motor5">
      <hardwareInterface>PositionJointInterface</hardwareInterface>
      <mechanicalReduction>1</mechanicalReduction>
      <drake:gear_ratio value="100.0" />
      <drake:rotor_inertia value="0.0000205544064" />
    </actuator>
  </transmission>
  <transmission name="panda_tran6">
    <type>transmission_interface/SimpleTransmission</type>
    <joint name="panda_joint6">
      <hardwareInterface>PositionJointInterface</hardwareInterface>
    </joint>
    <actuator name="panda_motor6">
      <hardwareInterface>PositionJointInterface</hardwareInterface>
      <mechanicalReduction>1</mechanicalReduction>
      <drake:gear_ratio value="100.0" />
      <drake:rotor_inertia value="0.0000205544064" />
    </actuator>
  </transmission>
  <transmission name="panda_tran7">
    <type>transmission_interface/SimpleTransmission</type>
    <joint name="panda_joint7">
      <hardwareInterface>PositionJointInterface</hardwareInterface>
    </joint>
    <actuator name="panda_motor7">
      <hardwareInterface>PositionJointInterface</hardwareInterface>
      <mechanicalReduction>1</mechanicalReduction>
      <drake:gear_ratio value="100.0" />
      <drake:rotor_inertia value="0.0000205544064" />
    </actuator>
  </transmission>
  <drake:collision_filter_group name="group_link57">
    <drake:member link="panda_link5"/>
    <drake:member link="panda_link7"/>
    <drake:ignored_collision_filter_group name="group_link57"/>
  </drake:collision_filter_group>
</robot>